2025-04-16 01:19:50,979 INFO    MainThread:295468 [wandb_setup.py:_flush():67] Current SDK version is 0.19.9
2025-04-16 01:19:50,980 INFO    MainThread:295468 [wandb_setup.py:_flush():67] Configure stats pid to 295468
2025-04-16 01:19:50,980 INFO    MainThread:295468 [wandb_setup.py:_flush():67] Loading settings from /home/nasir-hussain/.config/wandb/settings
2025-04-16 01:19:50,980 INFO    MainThread:295468 [wandb_setup.py:_flush():67] Loading settings from /home/nasir-hussain/Pictures/Depression_Detection_Using_Machine_Learning/wandb/settings
2025-04-16 01:19:50,980 INFO    MainThread:295468 [wandb_setup.py:_flush():67] Loading settings from environment variables
2025-04-16 01:19:50,980 INFO    MainThread:295468 [wandb_init.py:setup_run_log_directory():662] Logging user logs to /home/nasir-hussain/Pictures/Depression_Detection_Using_Machine_Learning/wandb/run-20250416_011950-cpcwgygk/logs/debug.log
2025-04-16 01:19:50,980 INFO    MainThread:295468 [wandb_init.py:setup_run_log_directory():663] Logging internal logs to /home/nasir-hussain/Pictures/Depression_Detection_Using_Machine_Learning/wandb/run-20250416_011950-cpcwgygk/logs/debug-internal.log
2025-04-16 01:19:50,980 INFO    MainThread:295468 [wandb_init.py:init():781] calling init triggers
2025-04-16 01:19:50,980 INFO    MainThread:295468 [wandb_init.py:init():786] wandb.init called with sweep_config: {}
config: {'_wandb': {}}
2025-04-16 01:19:50,980 INFO    MainThread:295468 [wandb_init.py:init():809] starting backend
2025-04-16 01:19:50,980 INFO    MainThread:295468 [wandb_init.py:init():813] sending inform_init request
2025-04-16 01:19:50,995 INFO    MainThread:295468 [backend.py:_multiprocessing_setup():101] multiprocessing start_methods=fork,spawn,forkserver, using: spawn
2025-04-16 01:19:50,995 INFO    MainThread:295468 [wandb_init.py:init():823] backend started and connected
2025-04-16 01:19:50,998 INFO    MainThread:295468 [wandb_init.py:init():915] updated telemetry
2025-04-16 01:19:51,008 INFO    MainThread:295468 [wandb_init.py:init():939] communicating run to backend with 90.0 second timeout
2025-04-16 01:19:52,076 INFO    MainThread:295468 [wandb_init.py:init():1014] starting run threads in backend
2025-04-16 01:19:52,349 INFO    MainThread:295468 [wandb_run.py:_console_start():2454] atexit reg
2025-04-16 01:19:52,351 INFO    MainThread:295468 [wandb_run.py:_redirect():2306] redirect: wrap_raw
2025-04-16 01:19:52,352 INFO    MainThread:295468 [wandb_run.py:_redirect():2371] Wrapping output streams.
2025-04-16 01:19:52,353 INFO    MainThread:295468 [wandb_run.py:_redirect():2394] Redirects installed.
2025-04-16 01:19:52,367 INFO    MainThread:295468 [wandb_init.py:init():1056] run started, returning control to user process
2025-04-16 01:20:05,584 INFO    MainThread:295468 [wandb_run.py:_finish():2189] finishing run adney377-amity-online/ml-classification-pipeline/cpcwgygk
2025-04-16 01:20:05,584 INFO    MainThread:295468 [wandb_run.py:_atexit_cleanup():2419] got exitcode: 0
2025-04-16 01:20:05,585 INFO    MainThread:295468 [wandb_run.py:_restore():2401] restore
2025-04-16 01:20:05,585 INFO    MainThread:295468 [wandb_run.py:_restore():2407] restore done
2025-04-16 01:22:26,203 WARNING MsgRouterThr:295468 [router.py:message_loop():63] [no run ID] message_loop has been closed
Traceback (most recent call last):
  File "/home/nasir-hussain/Pictures/Depression_Detection_Using_Machine_Learning/env/lib/python3.10/site-packages/wandb/sdk/interface/router_sock.py", line 27, in _read_message
    return self._sock_client.read_server_response(timeout=1)
  File "/home/nasir-hussain/Pictures/Depression_Detection_Using_Machine_Learning/env/lib/python3.10/site-packages/wandb/sdk/lib/sock_client.py", line 235, in read_server_response
    data = self._read_packet_bytes(timeout=timeout)
  File "/home/nasir-hussain/Pictures/Depression_Detection_Using_Machine_Learning/env/lib/python3.10/site-packages/wandb/sdk/lib/sock_client.py", line 220, in _read_packet_bytes
    raise SockClientClosedError
wandb.sdk.lib.sock_client.SockClientClosedError

The above exception was the direct cause of the following exception:

Traceback (most recent call last):
  File "/home/nasir-hussain/Pictures/Depression_Detection_Using_Machine_Learning/env/lib/python3.10/site-packages/wandb/sdk/interface/router.py", line 56, in message_loop
    msg = self._read_message()
  File "/home/nasir-hussain/Pictures/Depression_Detection_Using_Machine_Learning/env/lib/python3.10/site-packages/wandb/sdk/interface/router_sock.py", line 29, in _read_message
    raise MessageRouterClosedError from e
wandb.sdk.interface.router.MessageRouterClosedError
2025-04-16 01:22:26,204 INFO    MsgRouterThr:295468 [mailbox.py:close():129] [no run ID] Closing mailbox, abandoning 2 handles.
